Workbook

Sheet README
A2: Vintage Story Farming Dashboard
A3: Built for Vintage Story 1.22.1 stable + Specialized Classes 2.2.2 (specializedclasses)
A5: What this is
B6: A planning workbook for Vintage Story farming. The web app at https://garrethcline.github.io/vs-farming/ is the primary tool. This workbook is the math primer where the formulas were worked out before they got pushed into the React code. If you just want to plan a season, use the web app. If you want to read or audit the math cell-by-cell, this is where to look.
A8: Color legend (cell text colors)
B9: Blue text | C9: Hardcoded input. Change these to match your situation.
B10: Black text | C10: Computed by formula. Don't edit, it'll recompute when inputs change.
B11: Green text | C11: Pulled from another sheet (a cross-sheet link).
B12: Yellow fill | C12: Key assumption you might want to override (input cells).
B13: Red text | C13: Warning or critical info.
A14: ⚠ Versions and mod compatibility
A15: Built for Vintage Story 1.22.1 stable (released 29 April 2026). Supports one optional mod: Specialized Classes 2.2.2, mod identifier "specializedclasses", file SpecializedClasses.dll v2.2.2, built for VS 1.22.x. On the Settings tab, set "Has Farmhand fertilizer perk?" to TRUE if you have the mod and have taken the Farmhand class. Set to FALSE for vanilla. See SPEC.md §9 for the full perk math (decompiled from IL) and §15 for the underground farming bug status (still present in 1.22.1).
A16: Sheet index
B17: Settings | C17: Global config: server constants, climate, growth/damage rules. DaysPerMonth, DaysPerYear, and ClimateRows are named ranges. Most date arithmetic on other sheets pulls from them, so changing DaysPerMonth scales the year wraps. The Climate sheet itself stays at 108 rows; for a different DaysPerMonth, regenerate climate.csv.
B18: Climate | C18: 108-day temperature curve from your /debug exptempplot CSV. Drives the calendar and simulator.
B19: Crops | C19: All 18 plantable crops with JSON-verified params. Source data; don't edit unless game updates.
B20: Soils | C20: 5 soil tiers (poor / medium / compost / dirt / terra preta). Fertility values per tier.
B21: Fertilizers | C21: NPK table + interactive [MOD] Specialized Classes 'Fertilizer' perk calculator.
B22: Calendar | C22: Plantability heatmap across the full year. Toggle greenhouse on/off to compare.
B23: Simulator | C23: Pick a crop, plant day, soil tier. See full mechanics: stage time, damage flags, yield mul.
B24: Plots | C24: Track your active farm plots. Auto-computes harvest day, days remaining, status.
B25: Rotation | C25: N/P/K rotation history per plot. Suggests what to plant next.
B26: ActivityLog | C26: Append-only log of plant/harvest events for the season.
B27: Reference | C27: Glossary, key formulas explained, source citations.
A28: What lives in the app but not here | B28: rainfall + light/depth multipliers | C28: The web app Decision Helper multiplies a moisture factor (from biome rainfall) and a light/depth factor into grow speed. Those use Monte Carlo of the noise pipeline plus the formulas from BESoilNutrition.cs and BlockEntityFastForwardGrowth.cs. They are not in this spreadsheet yet; the app is the reference implementation.
A30: Quick start
B31: 1. Go to Settings → confirm DaysPerMonth = 9 and your latitude/climate values.
B32: 2. Visit Climate → temps are pre-loaded from your CSV. Chart shows yearly curve.
B33: 3. Calendar → see which crops can be planted on which days.
B34: 4. Simulator → try planting Rye on day 50: dropdown picks crop, predicts harvest.
B35: 5. Plots → enter your real plots, set crop + plant day, status auto-updates.
A38: Sources of truth
B39: SPEC.md is the master reference. Derived from vssurvivalmod-master (VS 1.22.1) + survival/blocktypes/plant/crop/*.json + SpecializedClasses.dll v2.2.2 IL decompilation. Climate from your /debug exptempplot CSV.
A45: Google Sheets note
A46: All charts are now PNG images for cross-app compatibility. Live counts (e.g., plot status) are shown as KPI cells alongside the chart. If you change inputs in Simulator or Fertilizers, the chart shows the default-state snapshot. The formulas above the chart still update live.

Sheet Decision
B1: Decision Helper
B2: Just harvested? Pick your next crop with full season context.
B5: 1 · Inputs
B7: Mode | C7: Standalone | D7: (Linked = pull data from a plot below)
B8: Plot ID | C8: P01 | D8: (only used in Linked mode)
B9: Today (day#) | C9: =CurrentDay -> 50 | D9: (pulls from Settings; overwrite to test other days)
B10: Soil tier | C10: =IF($C$7="Linked to Plots",INDEX(Plots!$D$7:$D$18,MATCH($C$8,Plots!$B$7:$B$18,0)),65) -> 65 | D10: (Barren=5, Low=25, Med=50, Compost=65, Terra Preta=80)
B11: Greenhouse? | C11: =IF($C$7="Linked to Plots",INDEX(Plots!$E$7:$E$18,MATCH($C$8,Plots!$B$7:$B$18,0)),FALSE()) -> FALSE | D11: (adds +5°C to all temperatures)
B12: [MOD] Has Farmhand fertilizer perk? | C12: =HasPerk -> TRUE | D12: [MOD: Specialized Classes - leave FALSE on vanilla] pulls from Settings
B13: Will fertilize at planting? | C13: =TRUE() -> TRUE | D13: (if TRUE, assumes you'll bring soil up to soil-tier before planting)
B14: Fertilizer to apply: | C14: None | D14: =IF($C$14="None","(no fertilizer)","+"&IFERROR(VLOOKUP($C$14,Fertilizers!$B$6:$E$9,2,FALSE()),0)&"N · +"&IFERROR(VLOOKUP($C$14,Fertilizers!$B$6:$E$9,3,FALSE()),0)&"P · +"&IFERROR(VLOOKUP($C$14,Fertilizers!$B$6:$E$9,4,FALSE()),0)&"K to slow-release pool") -> (no fertilizer) | I14: (only used if "Apply fertilizer at planting?" above is TRUE)
B15: Current N/P/K (post-harvest):
C16: N | E16: P | G16: K | I16: (0 to 100 each axis; defaults assume fertilized = soil tier; unfertilized = half soil tier)
C17: =IF($C$13,$C$10,IF($C$7="Linked to Plots",MAX(0,$C$10-30),$C$10/2)) -> 65 | E17: =IF($C$13,$C$10,IF($C$7="Linked to Plots",MAX(0,$C$10-30),$C$10/2)) -> 65 | G17: =IF($C$13,$C$10,IF($C$7="Linked to Plots",MAX(0,$C$10-30),$C$10/2)) -> 65
B18: Slow-release pool: | C18: 0 | E18: 0 | G18: 0 | I18: (0 to 150 each axis; check in-game F3 for 'Active fertilizer +X% N' display)
B19: 2 · Today's conditions
B21: Today is: | C21: ="Day "&$C$9&" ("&MOD($C$9-1,DaysPerMonth)+1&" "&CHOOSE(INT(($C$9-1)/DaysPerMonth)+1,"Jan","Feb","Mar","Apr","May","Jun","Jul","Aug","Sep","Oct","Nov","Dec")&")" -> Day 50 (5 Jun)
B22: Temperature today: | C22: =ROUND(IF($C$11,INDEX(Climate!$G$5:$G$112,$C$9),INDEX(Climate!$D$5:$D$112,$C$9)),1)&"°C avg" -> 13.5°C avg | D22: =ROUND(IF($C$11,INDEX(Climate!$H$5:$H$112,$C$9),INDEX(Climate!$E$5:$E$112,$C$9)),1)&"°C min" -> 4.7°C min | E22: =ROUND(IF($C$11,INDEX(Climate!$I$5:$I$112,$C$9),INDEX(Climate!$F$5:$F$112,$C$9)),1)&"°C max" -> 22.8°C max | F22: (varies through the day. Game uses tick temperature for damage)
B23: Growing days left: | C23: =IF($C$9>=SeasonEndDay,0,SeasonEndDay-$C$9)&" days" -> 34 days | D23: ="(season ends day "&SeasonEndDay&")" -> (season ends day 84)
B24: Lowest nutrient: | C24: =IF(MIN($C$17,$E$17,$G$17)=$C$17,"N",IF(MIN($C$17,$E$17,$G$17)=$E$17,"P","K"))&" ("&MIN($C$17,$E$17,$G$17)&")" -> N (65) | D24: ="(N-required crops will struggle if N is low; rotation matters)" -> (N-required crops will struggle if N is low; rotation matters)
B25: Verdict: | C25: =IF($C$9>SeasonEndDay,"Season has already ended. No outdoor planting until day 34",IF(SeasonEndDay-$C$9<10,"Less than 10 days left. Only fast crops will finish",IF(SeasonEndDay-$C$9<25,"Mid-late season. Pick fast/medium crops","Plenty of season left. Many options viable"))) -> Plenty of season left. Many options viable
B27: 3 · Crop ranking. All 18 crops scored for your situation
B29: Crop | C29: Grow days | D29: Plant→Harvest | E29: Days after | F29: Window min | G29: Window max | H29: Cold/heat? | I29: Frost OK? | J29: Rotation | K29: Follow-up? | L29: Score | M29: Verdict
B30: Rye | C30: =INDEX(Crops!$F$5:$F$22,MATCH("Rye",CropNames,0)) -> 16.02 | D30: =$C$9&"→"&IF(ROUND($C$9+$C30,0)>DaysPerYear,ROUND($C$9+$C30-DaysPerYear,0),ROUND($C$9+$C30,0)) -> 50→66 | E30: =MAX(0,ROUND(SeasonEndDay-($C$9+$C30),0)) -> 18 | F30: =IF($C$11,IF(ROUND($C$9+$C30,0)<=DaysPerYear,MIN(INDEX(Climate!$H$5:$H$112,$C$9):INDEX(Climate!$H$5:$H$112,ROUND($C$9+$C30,0))),MIN(MIN(INDEX(Climate!$H$5:$H$112,$C$9):INDEX(Climate!$H$5:$H$112,ClimateRows)),MIN(INDEX(Climate!$H$5:$H$112,1):INDEX(Climate!$H$5:$H$112,ROUND($C$9+$C30-DaysPerYear,0))))),IF(ROUND($C$9+$C30,0)<=DaysPerYear,MIN(INDEX(Climate!$E$5:$E$112,$C$9):INDEX(Climate!$E$5:$E$112,ROUND($C$9+$C30,0))),MIN(MIN(INDEX(Climate!$E$5:$E$112,$C$9):INDEX(Climate!$E$5:$E$112,ClimateRows)),MIN(INDEX(Climate!$E$5:$E$112,1):INDEX(Climate!$E$5:$E$112,ROUND($C$9+$C30-DaysPerYear,0)))))) -> 4.66 | G30: =IF($C$11,IF(ROUND($C$9+$C30,0)<=DaysPerYear,MAX(INDEX(Climate!$I$5:$I$112,$C$9):INDEX(Climate!$I$5:$I$112,ROUND($C$9+$C30,0))),MAX(MAX(INDEX(Climate!$I$5:$I$112,$C$9):INDEX(Climate!$I$5:$I$112,ClimateRows)),MAX(INDEX(Climate!$I$5:$I$112,1):INDEX(Climate!$I$5:$I$112,ROUND($C$9+$C30-DaysPerYear,0))))),IF(ROUND($C$9+$C30,0)<=DaysPerYear,MAX(INDEX(Climate!$F$5:$F$112,$C$9):INDEX(Climate!$F$5:$F$112,ROUND($C$9+$C30,0))),MAX(MAX(INDEX(Climate!$F$5:$F$112,$C$9):INDEX(Climate!$F$5:$F$112,ClimateRows)),MAX(INDEX(Climate!$F$5:$F$112,1):INDEX(Climate!$F$5:$F$112,ROUND($C$9+$C30-DaysPerYear,0)))))) -> 24.64 | H30: =IF(AND($F30<INDEX(Crops!$K$5:$K$22,MATCH("Rye",CropNames,0)),$G30>INDEX(Crops!$M$5:$M$22,MATCH("Rye",CropNames,0))),"C+H",IF($F30<INDEX(Crops!$K$5:$K$22,MATCH("Rye",CropNames,0)),"COLD",IF($G30>INDEX(Crops!$M$5:$M$22,MATCH("Rye",CropNames,0)),"HEAT","✓ ok"))) -> ✓ ok | I30: =IF($C$9+$C30>SeasonEndDay,"✗ no",IF(SeasonEndDay-($C$9+$C30)<3,"barely","✓ yes")) -> ✓ yes | J30: =IF(MAX($C$17,$E$17,$G$17)-MIN($C$17,$E$17,$G$17)<=5,"ok",IF(INDEX(Crops!$G$5:$G$22,MATCH("Rye",CropNames,0))="N",IF($C$17=MIN($C$17,$E$17,$G$17),"poor",IF($C$17=MAX($C$17,$E$17,$G$17),"great","ok")),IF(INDEX(Crops!$G$5:$G$22,MATCH("Rye",CropNames,0))="P",IF($E$17=MIN($C$17,$E$17,$G$17),"poor",IF($E$17=MAX($C$17,$E$17,$G$17),"great","ok")),IF($G$17=MIN($C$17,$E$17,$G$17),"poor",IF($G$17=MAX($C$17,$E$17,$G$17),"great","ok"))))) -> ok | K30: =IF($E30>=15,"yes (carrot)",IF($E30>=8,"yes (turnip)",IF($E30>=4,"maybe","no"))) -> yes (carrot) | L30: =ROUND(5.5/$C30*100*IF(((IF(INDEX(Crops!$G$5:$G$22,MATCH("Rye",CropNames,0))="N",$C$17,IF(INDEX(Crops!$G$5:$G$22,MATCH("Rye",CropNames,0))="P",$E$17,$G$17)))+(MAX(0,IF(INDEX(Crops!$G$5:$G$22,MATCH("Rye",CropNames,0))="N",$C$17,IF(INDEX(Crops!$G$5:$G$22,MATCH("Rye",CropNames,0))="P",$E$17,$G$17))-MAX(0,INDEX(Crops!$H$5:$H$22,MATCH("Rye",CropNames,0))-MIN(IF(INDEX(Crops!$G$5:$G$22,MATCH("Rye",CropNames,0))="N",MIN(150,$C$18+IF($C$13,IFERROR(VLOOKUP($C$14,Fertilizers!$B$6:$E$9,2,FALSE()),0),0)),IF(INDEX(Crops!$G$5:$G$22,MATCH("Rye",CropNames,0))="P",MIN(150,$E$18+IF($C$13,IFERROR(VLOOKUP($C$14,Fertilizers!$B$6:$E$9,3,FALSE()),0),0)),MIN(150,$G$18+IF($C$13,IFERROR(VLOOKUP($C$14,Fertilizers!$B$6:$E$9,4,FALSE()),0),0)))),0.25*$C30*TicksPerDay)))))/2>75,1.1,IF(((IF(INDEX(Crops!$G$5:$G$22,MATCH("Rye",CropNames,0))="N",$C$17,IF(INDEX(Crops!$G$5:$G$22,MATCH("Rye",CropNames,0))="P",$E$17,$G$17)))+(MAX(0,IF(INDEX(Crops!$G$5:$G$22,MATCH("Rye",CropNames,0))="N",$C$17,IF(INDEX(Crops!$G$5:$G$22,MATCH("Rye",CropNames,0))="P",$E$17,$G$17))-MAX(0,INDEX(Crops!$H$5:$H$22,MATCH("Rye",CropNames,0))-MIN(IF(INDEX(Crops!$G$5:$G$22,MATCH("Rye",CropNames,0))="N",MIN(150,$C$18+IF($C$13,IFERROR(VLOOKUP($C$14,Fertilizers!$B$6:$E$9,2,FALSE()),0),0)),IF(INDEX(Crops!$G$5:$G$22,MATCH("Rye",CropNames,0))="P",MIN(150,$E$18+IF($C$13,IFERROR(VLOOKUP($C$14,Fertilizers!$B$6:$E$9,3,FALSE()),0),0)),MIN(150,$G$18+IF($C$13,IFERROR(VLOOKUP($C$14,Fertilizers!$B$6:$E$9,4,FALSE()),0),0)))),0.25*$C30*TicksPerDay)))))/2>50,1,IF(((IF(INDEX(Crops!$G$5:$G$22,MATCH("Rye",CropNames,0))="N",$C$17,IF(INDEX(Crops!$G$5:$G$22,MATCH("Rye",CropNames,0))="P",$E$17,$G$17)))+(MAX(0,IF(INDEX(Crops!$G$5:$G$22,MATCH("Rye",CropNames,0))="N",$C$17,IF(INDEX(Crops!$G$5:$G$22,MATCH("Rye",CropNames,0))="P",$E$17,$G$17))-MAX(0,INDEX(Crops!$H$5:$H$22,MATCH("Rye",CropNames,0))-MIN(IF(INDEX(Crops!$G$5:$G$22,MATCH("Rye",CropNames,0))="N",MIN(150,$C$18+IF($C$13,IFERROR(VLOOKUP($C$14,Fertilizers!$B$6:$E$9,2,FALSE()),0),0)),IF(INDEX(Crops!$G$5:$G$22,MATCH("Rye",CropNames,0))="P",MIN(150,$E$18+IF($C$13,IFERROR(VLOOKUP($C$14,Fertilizers!$B$6:$E$9,3,FALSE()),0),0)),MIN(150,$G$18+IF($C$13,IFERROR(VLOOKUP($C$14,Fertilizers!$B$6:$E$9,4,FALSE()),0),0)))),0.25*$C30*TicksPerDay)))))/2>35,0.9,IF(((IF(INDEX(Crops!$G$5:$G$22,MATCH("Rye",CropNames,0))="N",$C$17,IF(INDEX(Crops!$G$5:$G$22,MATCH("Rye",CropNames,0))="P",$E$17,$G$17)))+(MAX(0,IF(INDEX(Crops!$G$5:$G$22,MATCH("Rye",CropNames,0))="N",$C$17,IF(INDEX(Crops!$G$5:$G$22,MATCH("Rye",CropNames,0))="P",$E$17,$G$17))-MAX(0,INDEX(Crops!$H$5:$H$22,MATCH("Rye",CropNames,0))-MIN(IF(INDEX(Crops!$G$5:$G$22,MATCH("Rye",CropNames,0))="N",MIN(150,$C$18+IF($C$13,IFERROR(VLOOKUP($C$14,Fertilizers!$B$6:$E$9,2,FALSE()),0),0)),IF(INDEX(Crops!$G$5:$G$22,MATCH("Rye",CropNames,0))="P",MIN(150,$E$18+IF($C$13,IFERROR(VLOOKUP($C$14,Fertilizers!$B$6:$E$9,3,FALSE()),0),0)),MIN(150,$G$18+IF($C$13,IFERROR(VLOOKUP($C$14,Fertilizers!$B$6:$E$9,4,FALSE()),0),0)))),0.25*$C30*TicksPerDay)))))/2>20,0.6,IF(((IF(INDEX(Crops!$G$5:$G$22,MATCH("Rye",CropNames,0))="N",$C$17,IF(INDEX(Crops!$G$5:$G$22,MATCH("Rye",CropNames,0))="P",$E$17,$G$17)))+(MAX(0,IF(INDEX(Crops!$G$5:$G$22,MATCH("Rye",CropNames,0))="N",$C$17,IF(INDEX(Crops!$G$5:$G$22,MATCH("Rye",CropNames,0))="P",$E$17,$G$17))-MAX(0,INDEX(Crops!$H$5:$H$22,MATCH("Rye",CropNames,0))-MIN(IF(INDEX(Crops!$G$5:$G$22,MATCH("Rye",CropNames,0))="N",MIN(150,$C$18+IF($C$13,IFERROR(VLOOKUP($C$14,Fertilizers!$B$6:$E$9,2,FALSE()),0),0)),IF(INDEX(Crops!$G$5:$G$22,MATCH("Rye",CropNames,0))="P",MIN(150,$E$18+IF($C$13,IFERROR(VLOOKUP($C$14,Fertilizers!$B$6:$E$9,3,FALSE()),0),0)),MIN(150,$G$18+IF($C$13,IFERROR(VLOOKUP($C$14,Fertilizers!$B$6:$E$9,4,FALSE()),0),0)))),0.25*$C30*TicksPerDay)))))/2>5,0.3,0.1)))))*IF($I30="✓ yes",1,IF($I30="barely",0.6,0))*IF($H30="✓ ok",1,IFERROR(IF(ISBLANK(INDEX(Crops!$O$5:$O$22,MATCH("Rye",CropNames,0))),DefaultStuntMul,INDEX(Crops!$O$5:$O$22,MATCH("Rye",CropNames,0))),DefaultStuntMul))*IF($J30="poor",0.7,IF($J30="great",1.2,1))*IF(LEFT($K30,3)="yes",1.3,IF($K30="maybe",1.1,1)),1) -> 40.2 | M30: =IF($I30="✗ no","won't finish",IF($H30="✓ ok",IF($L30>=RANK_TOP3,"top pick",IF($L30>=RANK_TOP10,"good","ok")),"risk: "&$H30)) -> good
B31: Carrot | C31: =INDEX(Crops!$F$5:$F$22,MATCH("Carrot",CropNames,0)) -> 9.27 | D31: =$C$9&"→"&IF(ROUND($C$9+$C31,0)>DaysPerYear,ROUND($C$9+$C31-DaysPerYear,0),ROUND($C$9+$C31,0)) -> 50→59 | E31: =MAX(0,ROUND(SeasonEndDay-($C$9+$C31),0)) -> 25 | F31: =IF($C$11,IF(ROUND($C$9+$C31,0)<=DaysPerYear,MIN(INDEX(Climate!$H$5:$H$112,$C$9):INDEX(Climate!$H$5:$H$112,ROUND($C$9+$C31,0))),MIN(MIN(INDEX(Climate!$H$5:$H$112,$C$9):INDEX(Climate!$H$5:$H$112,ClimateRows)),MIN(INDEX(Climate!$H$5:$H$112,1):INDEX(Climate!$H$5:$H$112,ROUND($C$9+$C31-DaysPerYear,0))))),IF(ROUND($C$9+$C31,0)<=DaysPerYear,MIN(INDEX(Climate!$E$5:$E$112,$C$9):INDEX(Climate!$E$5:$E$112,ROUND($C$9+$C31,0))),MIN(MIN(INDEX(Climate!$E$5:$E$112,$C$9):INDEX(Climate!$E$5:$E$112,ClimateRows)),MIN(INDEX(Climate!$E$5:$E$112,1):INDEX(Climate!$E$5:$E$112,ROUND($C$9+$C31-DaysPerYear,0)))))) -> 4.66 | G31: =IF($C$11,IF(ROUND($C$9+$C31,0)<=DaysPerYear,MAX(INDEX(Climate!$I$5:$I$112,$C$9):INDEX(Climate!$I$5:$I$112,ROUND($C$9+$C31,0))),MAX(MAX(INDEX(Climate!$I$5:$I$112,$C$9):INDEX(Climate!$I$5:$I$112,ClimateRows)),MAX(INDEX(Climate!$I$5:$I$112,1):INDEX(Climate!$I$5:$I$112,ROUND($C$9+$C31-DaysPerYear,0))))),IF(ROUND($C$9+$C31,0)<=DaysPerYear,MAX(INDEX(Climate!$F$5:$F$112,$C$9):INDEX(Climate!$F$5:$F$112,ROUND($C$9+$C31,0))),MAX(MAX(INDEX(Climate!$F$5:$F$112,$C$9):INDEX(Climate!$F$5:$F$112,ClimateRows)),MAX(INDEX(Climate!$F$5:$F$112,1):INDEX(Climate!$F$5:$F$112,ROUND($C$9+$C31-DaysPerYear,0)))))) -> 24.07 | H31: =IF(AND($F31<INDEX(Crops!$K$5:$K$22,MATCH("Carrot",CropNames,0)),$G31>INDEX(Crops!$M$5:$M$22,MATCH("Carrot",CropNames,0))),"C+H",IF($F31<INDEX(Crops!$K$5:$K$22,MATCH("Carrot",CropNames,0)),"COLD",IF($G31>INDEX(Crops!$M$5:$M$22,MATCH("Carrot",CropNames,0)),"HEAT","✓ ok"))) -> ✓ ok | I31: =IF($C$9+$C31>SeasonEndDay,"✗ no",IF(SeasonEndDay-($C$9+$C31)<3,"barely","✓ yes")) -> ✓ yes | J31: =IF(MAX($C$17,$E$17,$G$17)-MIN($C$17,$E$17,$G$17)<=5,"ok",IF(INDEX(Crops!$G$5:$G$22,MATCH("Carrot",CropNames,0))="N",IF($C$17=MIN($C$17,$E$17,$G$17),"poor",IF($C$17=MAX($C$17,$E$17,$G$17),"great","ok")),IF(INDEX(Crops!$G$5:$G$22,MATCH("Carrot",CropNames,0))="P",IF($E$17=MIN($C$17,$E$17,$G$17),"poor",IF($E$17=MAX($C$17,$E$17,$G$17),"great","ok")),IF($G$17=MIN($C$17,$E$17,$G$17),"poor",IF($G$17=MAX($C$17,$E$17,$G$17),"great","ok"))))) -> ok | K31: =IF($E31>=15,"yes (carrot)",IF($E31>=8,"yes (turnip)",IF($E31>=4,"maybe","no"))) -> yes (carrot) | L31: =ROUND(11/$C31*100*IF(((IF(INDEX(Crops!$G$5:$G$22,MATCH("Carrot",CropNames,0))="N",$C$17,IF(INDEX(Crops!$G$5:$G$22,MATCH("Carrot",CropNames,0))="P",$E$17,$G$17)))+(MAX(0,IF(INDEX(Crops!$G$5:$G$22,MATCH("Carrot",CropNames,0))="N",$C$17,IF(INDEX(Crops!$G$5:$G$22,MATCH("Carrot",CropNames,0))="P",$E$17,$G$17))-MAX(0,INDEX(Crops!$H$5:$H$22,MATCH("Carrot",CropNames,0))-MIN(IF(INDEX(Crops!$G$5:$G$22,MATCH("Carrot",CropNames,0))="N",MIN(150,$C$18+IF($C$13,IFERROR(VLOOKUP($C$14,Fertilizers!$B$6:$E$9,2,FALSE()),0),0)),IF(INDEX(Crops!$G$5:$G$22,MATCH("Carrot",CropNames,0))="P",MIN(150,$E$18+IF($C$13,IFERROR(VLOOKUP($C$14,Fertilizers!$B$6:$E$9,3,FALSE()),0),0)),MIN(150,$G$18+IF($C$13,IFERROR(VLOOKUP($C$14,Fertilizers!$B$6:$E$9,4,FALSE()),0),0)))),0.25*$C31*TicksPerDay)))))/2>75,1.1,IF(((IF(INDEX(Crops!$G$5:$G$22,MATCH("Carrot",CropNames,0))="N",$C$17,IF(INDEX(Crops!$G$5:$G$22,MATCH("Carrot",CropNames,0))="P",$E$17,$G$17)))+(MAX(0,IF(INDEX(Crops!$G$5:$G$22,MATCH("Carrot",CropNames,0))="N",$C$17,IF(INDEX(Crops!$G$5:$G$22,MATCH("Carrot",CropNames,0))="P",$E$17,$G$17))-MAX(0,INDEX(Crops!$H$5:$H$22,MATCH("Carrot",CropNames,0))-MIN(IF(INDEX(Crops!$G$5:$G$22,MATCH("Carrot",CropNames,0))="N",MIN(150,$C$18+IF($C$13,IFERROR(VLOOKUP($C$14,Fertilizers!$B$6:$E$9,2,FALSE()),0),0)),IF(INDEX(Crops!$G$5:$G$22,MATCH("Carrot",CropNames,0))="P",MIN(150,$E$18+IF($C$13,IFERROR(VLOOKUP($C$14,Fertilizers!$B$6:$E$9,3,FALSE()),0),0)),MIN(150,$G$18+IF($C$13,IFERROR(VLOOKUP($C$14,Fertilizers!$B$6:$E$9,4,FALSE()),0),0)))),0.25*$C31*TicksPerDay)))))/2>50,1,IF(((IF(INDEX(Crops!$G$5:$G$22,MATCH("Carrot",CropNames,0))="N",$C$17,IF(INDEX(Crops!$G$5:$G$22,MATCH("Carrot",CropNames,0))="P",$E$17,$G$17)))+(MAX(0,IF(INDEX(Crops!$G$5:$G$22,MATCH("Carrot",CropNames,0))="N",$C$17,IF(INDEX(Crops!$G$5:$G$22,MATCH("Carrot",CropNames,0))="P",$E$17,$G$17))-MAX(0,INDEX(Crops!$H$5:$H$22,MATCH("Carrot",CropNames,0))-MIN(IF(INDEX(Crops!$G$5:$G$22,MATCH("Carrot",CropNames,0))="N",MIN(150,$C$18+IF($C$13,IFERROR(VLOOKUP($C$14,Fertilizers!$B$6:$E$9,2,FALSE()),0),0)),IF(INDEX(Crops!$G$5:$G$22,MATCH("Carrot",CropNames,0))="P",MIN(150,$E$18+IF($C$13,IFERROR(VLOOKUP($C$14,Fertilizers!$B$6:$E$9,3,FALSE()),0),0)),MIN(150,$G$18+IF($C$13,IFERROR(VLOOKUP($C$14,Fertilizers!$B$6:$E$9,4,FALSE()),0),0)))),0.25*$C31*TicksPerDay)))))/2>35,0.9,IF(((IF(INDEX(Crops!$G$5:$G$22,MATCH("Carrot",CropNames,0))="N",$C$17,IF(INDEX(Crops!$G$5:$G$22,MATCH("Carrot",CropNames,0))="P",$E$17,$G$17)))+(MAX(0,IF(INDEX(Crops!$G$5:$G$22,MATCH("Carrot",CropNames,0))="N",$C$17,IF(INDEX(Crops!$G$5:$G$22,MATCH("Carrot",CropNames,0))="P",$E$17,$G$17))-MAX(0,INDEX(Crops!$H$5:$H$22,MATCH("Carrot",CropNames,0))-MIN(IF(INDEX(Crops!$G$5:$G$22,MATCH("Carrot",CropNames,0))="N",MIN(150,$C$18+IF($C$13,IFERROR(VLOOKUP($C$14,Fertilizers!$B$6:$E$9,2,FALSE()),0),0)),IF(INDEX(Crops!$G$5:$G$22,MATCH("Carrot",CropNames,0))="P",MIN(150,$E$18+IF($C$13,IFERROR(VLOOKUP($C$14,Fertilizers!$B$6:$E$9,3,FALSE()),0),0)),MIN(150,$G$18+IF($C$13,IFERROR(VLOOKUP($C$14,Fertilizers!$B$6:$E$9,4,FALSE()),0),0)))),0.25*$C31*TicksPerDay)))))/2>20,0.6,IF(((IF(INDEX(Crops!$G$5:$G$22,MATCH("Carrot",CropNames,0))="N",$C$17,IF(INDEX(Crops!$G$5:$G$22,MATCH("Carrot",CropNames,0))="P",$E$17,$G$17)))+(MAX(0,IF(INDEX(Crops!$G$5:$G$22,MATCH("Carrot",CropNames,0))="N",$C$17,IF(INDEX(Crops!$G$5:$G$22,MATCH("Carrot",CropNames,0))="P",$E$17,$G$17))-MAX(0,INDEX(Crops!$H$5:$H$22,MATCH("Carrot",CropNames,0))-MIN(IF(INDEX(Crops!$G$5:$G$22,MATCH("Carrot",CropNames,0))="N",MIN(150,$C$18+IF($C$13,IFERROR(VLOOKUP($C$14,Fertilizers!$B$6:$E$9,2,FALSE()),0),0)),IF(INDEX(Crops!$G$5:$G$22,MATCH("Carrot",CropNames,0))="P",MIN(150,$E$18+IF($C$13,IFERROR(VLOOKUP($C$14,Fertilizers!$B$6:$E$9,3,FALSE()),0),0)),MIN(150,$G$18+IF($C$13,IFERROR(VLOOKUP($C$14,Fertilizers!$B$6:$E$9,4,FALSE()),0),0)))),0.25*$C31*TicksPerDay)))))/2>5,0.3,0.1)))))*IF($I31="✓ yes",1,IF($I31="barely",0.6,0))*IF($H31="✓ ok",1,IFERROR(IF(ISBLANK(INDEX(Crops!$O$5:$O$22,MATCH("Carrot",CropNames,0))),DefaultStuntMul,INDEX(Crops!$O$5:$O$22,MATCH("Carrot",CropNames,0))),DefaultStuntMul))*IF($J31="poor",0.7,IF($J31="great",1.2,1))*IF(LEFT($K31,3)="yes",1.3,IF($K31="maybe",1.1,1)),1) -> 138.8 | M31: =IF($I31="✗ no","won't finish",IF($H31="✓ ok",IF($L31>=RANK_TOP3,"top pick",IF($L31>=RANK_TOP10,"good","ok")),"risk: "&$H31)) -> top pick
B32: Parsnip | C32: =INDEX(Crops!$F$5:$F$22,MATCH("Parsnip",CropNames,0)) -> 15.75 | D32: =$C$9&"→"&IF(ROUND($C$9+$C32,0)>DaysPerYear,ROUND($C$9+$C32-DaysPerYear,0),ROUND($C$9+$C32,0)) -> 50→66 | E32: =MAX(0,ROUND(SeasonEndDay-($C$9+$C32),0)) -> 18 | F32: =IF($C$11,IF(ROUND($C$9+$C32,0)<=DaysPerYear,MIN(INDEX(Climate!$H$5:$H$112,$C$9):INDEX(Climate!$H$5:$H$112,ROUND($C$9+$C32,0))),MIN(MIN(INDEX(Climate!$H$5:$H$112,$C$9):INDEX(Climate!$H$5:$H$112,ClimateRows)),MIN(INDEX(Climate!$H$5:$H$112,1):INDEX(Climate!$H$5:$H$112,ROUND($C$9+$C32-DaysPerYear,0))))),IF(ROUND($C$9+$C32,0)<=DaysPerYear,MIN(INDEX(Climate!$E$5:$E$112,$C$9):INDEX(Climate!$E$5:$E$112,ROUND($C$9+$C32,0))),MIN(MIN(INDEX(Climate!$E$5:$E$112,$C$9):INDEX(Climate!$E$5:$E$112,ClimateRows)),MIN(INDEX(Climate!$E$5:$E$112,1):INDEX(Climate!$E$5:$E$112,ROUND($C$9+$C32-DaysPerYear,0)))))) -> 4.66 | G32: =IF($C$11,IF(ROUND($C$9+$C32,0)<=DaysPerYear,MAX(INDEX(Climate!$I$5:$I$112,$C$9):INDEX(Climate!$I$5:$I$112,ROUND($C$9+$C32,0))),MAX(MAX(INDEX(Climate!$I$5:$I$112,$C$9):INDEX(Climate!$I$5:$I$112,ClimateRows)),MAX(INDEX(Climate!$I$5:$I$112,1):INDEX(Climate!$I$5:$I$112,ROUND($C$9+$C32-DaysPerYear,0))))),IF(ROUND($C$9+$C32,0)<=DaysPerYear,MAX(INDEX(Climate!$F$5:$F$112,$C$9):INDEX(Climate!$F$5:$F$112,ROUND($C$9+$C32,0))),MAX(MAX(INDEX(Climate!$F$5:$F$112,$C$9):INDEX(Climate!$F$5:$F$112,ClimateRows)),MAX(INDEX(Climate!$F$5:$F$112,1):INDEX(Climate!$F$5:$F$112,ROUND($C$9+$C32-DaysPerYear,0)))))) -> 24.64 | H32: =IF(AND($F32<INDEX(Crops!$K$5:$K$22,MATCH("Parsnip",CropNames,0)),$G32>INDEX(Crops!$M$5:$M$22,MATCH("Parsnip",CropNames,0))),"C+H",IF($F32<INDEX(Crops!$K$5:$K$22,MATCH("Parsnip",CropNames,0)),"COLD",IF($G32>INDEX(Crops!$M$5:$M$22,MATCH("Parsnip",CropNames,0)),"HEAT","✓ ok"))) -> ✓ ok | I32: =IF($C$9+$C32>SeasonEndDay,"✗ no",IF(SeasonEndDay-($C$9+$C32)<3,"barely","✓ yes")) -> ✓ yes | J32: =IF(MAX($C$17,$E$17,$G$17)-MIN($C$17,$E$17,$G$17)<=5,"ok",IF(INDEX(Crops!$G$5:$G$22,MATCH("Parsnip",CropNames,0))="N",IF($C$17=MIN($C$17,$E$17,$G$17),"poor",IF($C$17=MAX($C$17,$E$17,$G$17),"great","ok")),IF(INDEX(Crops!$G$5:$G$22,MATCH("Parsnip",CropNames,0))="P",IF($E$17=MIN($C$17,$E$17,$G$17),"poor",IF($E$17=MAX($C$17,$E$17,$G$17),"great","ok")),IF($G$17=MIN($C$17,$E$17,$G$17),"poor",IF($G$17=MAX($C$17,$E$17,$G$17),"great","ok"))))) -> ok | K32: =IF($E32>=15,"yes (carrot)",IF($E32>=8,"yes (turnip)",IF($E32>=4,"maybe","no"))) -> yes (carrot) | L32: =ROUND(12/$C32*100*IF(((IF(INDEX(Crops!$G$5:$G$22,MATCH("Parsnip",CropNames,0))="N",$C$17,IF(INDEX(Crops!$G$5:$G$22,MATCH("Parsnip",CropNames,0))="P",$E$17,$G$17)))+(MAX(0,IF(INDEX(Crops!$G$5:$G$22,MATCH("Parsnip",CropNames,0))="N",$C$17,IF(INDEX(Crops!$G$5:$G$22,MATCH("Parsnip",CropNames,0))="P",$E$17,$G$17))-MAX(0,INDEX(Crops!$H$5:$H$22,MATCH("Parsnip",CropNames,0))-MIN(IF(INDEX(Crops!$G$5:$G$22,MATCH("Parsnip",CropNames,0))="N",MIN(150,$C$18+IF($C$13,IFERROR(VLOOKUP($C$14,Fertilizers!$B$6:$E$9,2,FALSE()),0),0)),IF(INDEX(Crops!$G$5:$G$22,MATCH("Parsnip",CropNames,0))="P",MIN(150,$E$18+IF($C$13,IFERROR(VLOOKUP($C$14,Fertilizers!$B$6:$E$9,3,FALSE()),0),0)),MIN(150,$G$18+IF($C$13,IFERROR(VLOOKUP($C$14,Fertilizers!$B$6:$E$9,4,FALSE()),0),0)))),0.25*$C32*TicksPerDay)))))/2>75,1.1,IF(((IF(INDEX(Crops!$G$5:$G$22,MATCH("Parsnip",CropNames,0))="N",$C$17,IF(INDEX(Crops!$G$5:$G$22,MATCH("Parsnip",CropNames,0))="P",$E$17,$G$17)))+(MAX(0,IF(INDEX(Crops!$G$5:$G$22,MATCH("Parsnip",CropNames,0))="N",$C$17,IF(INDEX(Crops!$G$5:$G$22,MATCH("Parsnip",CropNames,0))="P",$E$17,$G$17))-MAX(0,INDEX(Crops!$H$5:$H$22,MATCH("Parsnip",CropNames,0))-MIN(IF(INDEX(Crops!$G$5:$G$22,MATCH("Parsnip",CropNames,0))="N",MIN(150,$C$18+IF($C$13,IFERROR(VLOOKUP($C$14,Fertilizers!$B$6:$E$9,2,FALSE()),0),0)),IF(INDEX(Crops!$G$5:$G$22,MATCH("Parsnip",CropNames,0))="P",MIN(150,$E$18+IF($C$13,IFERROR(VLOOKUP($C$14,Fertilizers!$B$6:$E$9,3,FALSE()),0),0)),MIN(150,$G$18+IF($C$13,IFERROR(VLOOKUP($C$14,Fertilizers!$B$6:$E$9,4,FALSE()),0),0)))),0.25*$C32*TicksPerDay)))))/2>50,1,IF(((IF(INDEX(Crops!$G$5:$G$22,MATCH("Parsnip",CropNames,0))="N",$C$17,IF(INDEX(Crops!$G$5:$G$22,MATCH("Parsnip",CropNames,0))="P",$E$17,$G$17)))+(MAX(0,IF(INDEX(Crops!$G$5:$G$22,MATCH("Parsnip",CropNames,0))="N",$C$17,IF(INDEX(Crops!$G$5:$G$22,MATCH("Parsnip",CropNames,0))="P",$E$17,$G$17))-MAX(0,INDEX(Crops!$H$5:$H$22,MATCH("Parsnip",CropNames,0))-MIN(IF(INDEX(Crops!$G$5:$G$22,MATCH("Parsnip",CropNames,0))="N",MIN(150,$C$18+IF($C$13,IFERROR(VLOOKUP($C$14,Fertilizers!$B$6:$E$9,2,FALSE()),0),0)),IF(INDEX(Crops!$G$5:$G$22,MATCH("Parsnip",CropNames,0))="P",MIN(150,$E$18+IF($C$13,IFERROR(VLOOKUP($C$14,Fertilizers!$B$6:$E$9,3,FALSE()),0),0)),MIN(150,$G$18+IF($C$13,IFERROR(VLOOKUP($C$14,Fertilizers!$B$6:$E$9,4,FALSE()),0),0)))),0.25*$C32*TicksPerDay)))))/2>35,0.9,IF(((IF(INDEX(Crops!$G$5:$G$22,MATCH("Parsnip",CropNames,0))="N",$C$17,IF(INDEX(Crops!$G$5:$G$22,MATCH("Parsnip",CropNames,0))="P",$E$17,$G$17)))+(MAX(0,IF(INDEX(Crops!$G$5:$G$22,MATCH("Parsnip",CropNames,0))="N",$C$17,IF(INDEX(Crops!$G$5:$G$22,MATCH("Parsnip",CropNames,0))="P",$E$17,$G$17))-MAX(0,INDEX(Crops!$H$5:$H$22,MATCH("Parsnip",CropNames,0))-MIN(IF(INDEX(Crops!$G$5:$G$22,MATCH("Parsnip",CropNames,0))="N",MIN(150,$C$18+IF($C$13,IFERROR(VLOOKUP($C$14,Fertilizers!$B$6:$E$9,2,FALSE()),0),0)),IF(INDEX(Crops!$G$5:$G$22,MATCH("Parsnip",CropNames,0))="P",MIN(150,$E$18+IF($C$13,IFERROR(VLOOKUP($C$14,Fertilizers!$B$6:$E$9,3,FALSE()),0),0)),MIN(150,$G$18+IF($C$13,IFERROR(VLOOKUP($C$14,Fertilizers!$B$6:$E$9,4,FALSE()),0),0)))),0.25*$C32*TicksPerDay)))))/2>20,0.6,IF(((IF(INDEX(Crops!$G$5:$G$22,MATCH("Parsnip",CropNames,0))="N",$C$17,IF(INDEX(Crops!$G$5:$G$22,MATCH("Parsnip",CropNames,0))="P",$E$17,$G$17)))+(MAX(0,IF(INDEX(Crops!$G$5:$G$22,MATCH("Parsnip",CropNames,0))="N",$C$17,IF(INDEX(Crops!$G$5:$G$22,MATCH("Parsnip",CropNames,0))="P",$E$17,$G$17))-MAX(0,INDEX(Crops!$H$5:$H$22,MATCH("Parsnip",CropNames,0))-MIN(IF(INDEX(Crops!$G$5:$G$22,MATCH("Parsnip",CropNames,0))="N",MIN(150,$C$18+IF($C$13,IFERROR(VLOOKUP($C$14,Fertilizers!$B$6:$E$9,2,FALSE()),0),0)),IF(INDEX(Crops!$G$5:$G$22,MATCH("Parsnip",CropNames,0))="P",MIN(150,$E$18+IF($C$13,IFERROR(VLOOKUP($C$14,Fertilizers!$B$6:$E$9,3,FALSE()),0),0)),MIN(150,$G$18+IF($C$13,IFERROR(VLOOKUP($C$14,Fertilizers!$B$6:$E$9,4,FALSE()),0),0)))),0.25*$C32*TicksPerDay)))))/2>5,0.3,0.1)))))*IF($I32="✓ yes",1,IF($I32="barely",0.6,0))*IF($H32="✓ ok",1,IFERROR(IF(ISBLANK(INDEX(Crops!$O$5:$O$22,MATCH("Parsnip",CropNames,0))),DefaultStuntMul,INDEX(Crops!$O$5:$O$22,MATCH("Parsnip",CropNames,0))),DefaultStuntMul))*IF($J32="poor",0.7,IF($J32="great",1.2,1))*IF(LEFT($K32,3)="yes",1.3,IF($K32="maybe",1.1,1)),1) -> 99 | M32: =IF($I32="✗ no","won't finish",IF($H32="✓ ok",IF($L32>=RANK_TOP3,"top pick",IF($L32>=RANK_TOP10,"good","ok")),"risk: "&$H32)) -> good
B33: Fennel | C33: =INDEX(Crops!$F$5:$F$22,MATCH("Fennel",CropNames,0)) -> 24.03 | D33: =$C$9&"→"&IF(ROUND($C$9+$C33,0)>DaysPerYear,ROUND($C$9+$C33-DaysPerYear,0),ROUND($C$9+$C33,0)) -> 50→74 | E33: =MAX(0,ROUND(SeasonEndDay-($C$9+$C33),0)) -> 10 | F33: =IF($C$11,IF(ROUND($C$9+$C33,0)<=DaysPerYear,MIN(INDEX(Climate!$H$5:$H$112,$C$9):INDEX(Climate!$H$5:$H$112,ROUND($C$9+$C33,0))),MIN(MIN(INDEX(Climate!$H$5:$H$112,$C$9):INDEX(Climate!$H$5:$H$112,ClimateRows)),MIN(INDEX(Climate!$H$5:$H$112,1):INDEX(Climate!$H$5:$H$112,ROUND($C$9+$C33-DaysPerYear,0))))),IF(ROUND($C$9+$C33,0)<=DaysPerYear,MIN(INDEX(Climate!$E$5:$E$112,$C$9):INDEX(Climate!$E$5:$E$112,ROUND($C$9+$C33,0))),MIN(MIN(INDEX(Climate!$E$5:$E$112,$C$9):INDEX(Climate!$E$5:$E$112,ClimateRows)),MIN(INDEX(Climate!$E$5:$E$112,1):INDEX(Climate!$E$5:$E$112,ROUND($C$9+$C33-DaysPerYear,0)))))) -> 1.96 | G33: =IF($C$11,IF(ROUND($C$9+$C33,0)<=DaysPerYear,MAX(INDEX(Climate!$I$5:$I$112,$C$9):INDEX(Climate!$I$5:$I$112,ROUND($C$9+$C33,0))),MAX(MAX(INDEX(Climate!$I$5:$I$112,$C$9):INDEX(Climate!$I$5:$I$112,ClimateRows)),MAX(INDEX(Climate!$I$5:$I$112,1):INDEX(Climate!$I$5:$I$112,ROUND($C$9+$C33-DaysPerYear,0))))),IF(ROUND($C$9+$C33,0)<=DaysPerYear,MAX(INDEX(Climate!$F$5:$F$112,$C$9):INDEX(Climate!$F$5:$F$112,ROUND($C$9+$C33,0))),MAX(MAX(INDEX(Climate!$F$5:$F$112,$C$9):INDEX(Climate!$F$5:$F$112,ClimateRows)),MAX(INDEX(Climate!$F$5:$F$112,1):INDEX(Climate!$F$5:$F$112,ROUND($C$9+$C33-DaysPerYear,0)))))) -> 24.64 | H33: =IF(AND($F33<INDEX(Crops!$K$5:$K$22,MATCH("Fennel",CropNames,0)),$G33>INDEX(Crops!$M$5:$M$22,MATCH("Fennel",CropNames,0))),"C+H",IF($F33<INDEX(Crops!$K$5:$K$22,MATCH("Fennel",CropNames,0)),"COLD",IF($G33>INDEX(Crops!$M$5:$M$22,MATCH("Fennel",CropNames,0)),"HEAT","✓ ok"))) -> ✓ ok | I33: =IF($C$9+$C33>SeasonEndDay,"✗ no",IF(SeasonEndDay-($C$9+$C33)<3,"barely","✓ yes")) -> ✓ yes | J33: =IF(MAX($C$17,$E$17,$G$17)-MIN($C$17,$E$17,$G$17)<=5,"ok",IF(INDEX(Crops!$G$5:$G$22,MATCH("Fennel",CropNames,0))="N",IF($C$17=MIN($C$17,$E$17,$G$17),"poor",IF($C$17=MAX($C$17,$E$17,$G$17),"great","ok")),IF(INDEX(Crops!$G$5:$G$22,MATCH("Fennel",CropNames,0))="P",IF($E$17=MIN($C$17,$E$17,$G$17),"poor",IF($E$17=MAX($C$17,$E$17,$G$17),"great","ok")),IF($G$17=MIN($C$17,$E$17,$G$17),"poor",IF($G$17=MAX($C$17,$E$17,$G$17),"great","ok"))))) -> ok | K33: =IF($E33>=15,"yes (carrot)",IF($E33>=8,"yes (turnip)",IF($E33>=4,"maybe","no"))) -> yes (turnip) | L33: =ROUND(11/$C33*100*IF(((IF(INDEX(Crops!$G$5:$G$22,MATCH("Fennel",CropNames,0))="N",$C$17,IF(INDEX(Crops!$G$5:$G$22,MATCH("Fennel",CropNames,0))="P",$E$17,$G$17)))+(MAX(0,IF(INDEX(Crops!$G$5:$G$22,MATCH("Fennel",CropNames,0))="N",$C$17,IF(INDEX(Crops!$G$5:$G$22,MATCH("Fennel",CropNames,0))="P",$E$17,$G$17))-MAX(0,INDEX(Crops!$H$5:$H$22,MATCH("Fennel",CropNames,0))-MIN(IF(INDEX(Crops!$G$5:$G$22,MATCH("Fennel",CropNames,0))="N",MIN(150,$C$18+IF($C$13,IFERROR(VLOOKUP($C$14,Fertilizers!$B$6:$E$9,2,FALSE()),0),0)),IF(INDEX(Crops!$G$5:$G$22,MATCH("Fennel",CropNames,0))="P",MIN(150,$E$18+IF($C$13,IFERROR(VLOOKUP($C$14,Fertilizers!$B$6:$E$9,3,FALSE()),0),0)),MIN(150,$G$18+IF($C$13,IFERROR(VLOOKUP($C$14,Fertilizers!$B$6:$E$9,4,FALSE()),0),0)))),0.25*$C33*TicksPerDay)))))/2>75,1.1,IF(((IF(INDEX(Crops!$G$5:$G$22,MATCH("Fennel",CropNames,0))="N",$C$17,IF(INDEX(Crops!$G$5:$G$22,MATCH("Fennel",CropNames,0))="P",$E$17,$G$17)))+(MAX(0,IF(INDEX(Crops!$G$5:$G$22,MATCH("Fennel",CropNames,0))="N",$C$17,IF(INDEX(Crops!$G$5:$G$22,MATCH("Fennel",CropNames,0))="P",$E$17,$G$17))-MAX(0,INDEX(Crops!$H$5:$H$22,MATCH("Fennel",CropNames,0))-MIN(IF(INDEX(Crops!$G$5:$G$22,MATCH("Fennel",CropNames,0))="N",MIN(150,$C$18+IF($C$13,IFERROR(VLOOKUP($C$14,Fertilizers!$B$6:$E$9,2,FALSE()),0),0)),IF(INDEX(Crops!$G$5:$G$22,MATCH("Fennel",CropNames,0))="P",MIN(150,$E$18+IF($C$13,IFERROR(VLOOKUP($C$14,Fertilizers!$B$6:$E$9,3,FALSE()),0),0)),MIN(150,$G$18+IF($C$13,IFERROR(VLOOKUP($C$14,Fertilizers!$B$6:$E$9,4,FALSE()),0),0)))),0.25*$C33*TicksPerDay)))))/2>50,1,IF(((IF(INDEX(Crops!$G$5:$G$22,MATCH("Fennel",CropNames,0))="N",$C$17,IF(INDEX(Crops!$G$5:$G$22,MATCH("Fennel",CropNames,0))="P",$E$17,$G$17)))+(MAX(0,IF(INDEX(Crops!$G$5:$G$22,MATCH("Fennel",CropNames,0))="N",$C$17,IF(INDEX(Crops!$G$5:$G$22,MATCH("Fennel",CropNames,0))="P",$E$17,$G$17))-MAX(0,INDEX(Crops!$H$5:$H$22,MATCH("Fennel",CropNames,0))-MIN(IF(INDEX(Crops!$G$5:$G$22,MATCH("Fennel",CropNames,0))="N",MIN(150,$C$18+IF($C$13,IFERROR(VLOOKUP($C$14,Fertilizers!$B$6:$E$9,2,FALSE()),0),0)),IF(INDEX(Crops!$G$5:$G$22,MATCH("Fennel",CropNames,0))="P",MIN(150,$E$18+IF($C$13,IFERROR(VLOOKUP($C$14,Fertilizers!$B$6:$E$9,3,FALSE()),0),0)),MIN(150,$G$18+IF($C$13,IFERROR(VLOOKUP($C$14,Fertilizers!$B$6:$E$9,4,FALSE()),0),0)))),0.25*$C33*TicksPerDay)))))/2>35,0.9,IF(((IF(INDEX(Crops!$G$5:$G$22,MATCH("Fennel",CropNames,0))="N",$C$17,IF(INDEX(Crops!$G$5:$G$22,MATCH("Fennel",CropNames,0))="P",$E$17,$G$17)))+(MAX(0,IF(INDEX(Crops!$G$5:$G$22,MATCH("Fennel",CropNames,0))="N",$C$17,IF(INDEX(Crops!$G$5:$G$22,MATCH("Fennel",CropNames,0))="P",$E$17,$G$17))-MAX(0,INDEX(Crops!$H$5:$H$22,MATCH("Fennel",CropNames,0))-MIN(IF(INDEX(Crops!$G$5:$G$22,MATCH("Fennel",CropNames,0))="N",MIN(150,$C$18+IF($C$13,IFERROR(VLOOKUP($C$14,Fertilizers!$B$6:$E$9,2,FALSE()),0),0)),IF(INDEX(Crops!$G$5:$G$22,MATCH("Fennel",CropNames,0))="P",MIN(150,$E$18+IF($C$13,IFERROR(VLOOKUP($C$14,Fertilizers!$B$6:$E$9,3,FALSE()),0),0)),MIN(150,$G$18+IF($C$13,IFERROR(VLOOKUP($C$14,Fertilizers!$B$6:$E$9,4,FALSE()),0),0)))),0.25*$C33*TicksPerDay)))))/2>20,0.6,IF(((IF(INDEX(Crops!$G$5:$G$22,MATCH("Fennel",CropNames,0))="N",$C$17,IF(INDEX(Crops!$G$5:$G$22,MATCH("Fennel",CropNames,0))="P",$E$17,$G$17)))+(MAX(0,IF(INDEX(Crops!$G$5:$G$22,MATCH("Fennel",CropNames,0))="N",$C$17,IF(INDEX(Crops!$G$5:$G$22,MATCH("Fennel",CropNames,0))="P",$E$17,$G$17))-MAX(0,INDEX(Crops!$H$5:$H$22,MATCH("Fennel",CropNames,0))-MIN(IF(INDEX(Crops!$G$5:$G$22,MATCH("Fennel",CropNames,0))="N",MIN(150,$C$18+IF($C$13,IFERROR(VLOOKUP($C$14,Fertilizers!$B$6:$E$9,2,FALSE()),0),0)),IF(INDEX(Crops!$G$5:$G$22,MATCH("Fennel",CropNames,0))="P",MIN(150,$E$18+IF($C$13,IFERROR(VLOOKUP($C$14,Fertilizers!$B$6:$E$9,3,FALSE()),0),0)),MIN(150,$G$18+IF($C$13,IFERROR(VLOOKUP($C$14,Fertilizers!$B$6:$E$9,4,FALSE()),0),0)))),0.25*$C33*TicksPerDay)))))/2>5,0.3,0.1)))))*IF($I33="✓ yes",1,IF($I33="barely",0.6,0))*IF($H33="✓ ok",1,IFERROR(IF(ISBLANK(INDEX(Crops!$O$5:$O$22,MATCH("Fennel",CropNames,0))),DefaultStuntMul,INDEX(Crops!$O$5:$O$22,MATCH("Fennel",CropNames,0))),DefaultStuntMul))*IF($J33="poor",0.7,IF($J33="great",1.2,1))*IF(LEFT($K33,3)="yes",1.3,IF($K33="maybe",1.1,1)),1) -> 53.6 | M33: =IF($I33="✗ no","won't finish",IF($H33="✓ ok",IF($L33>=RANK_TOP3,"top pick",IF($L33>=RANK_TOP10,"good","ok")),"risk: "&$H33)) -> good
B34: Licorice | C34: =INDEX(Crops!$F$5:$F$22,MATCH("Licorice",CropNames,0)) -> 24.03 | D34: =$C$9&"→"&IF(ROUND($C$9+$C34,0)>DaysPerYear,ROUND($C$9+$C34-DaysPerYear,0),ROUND($C$9+$C34,0)) -> 50→74 | E34: =MAX(0,ROUND(SeasonEndDay-($C$9+$C34),0)) -> 10 | F34: =IF($C$11,IF(ROUND($C$9+$C34,0)<=DaysPerYear,MIN(INDEX(Climate!$H$5:$H$112,$C$9):INDEX(Climate!$H$5:$H$112,ROUND($C$9+$C34,0))),MIN(MIN(INDEX(Climate!$H$5:$H$112,$C$9):INDEX(Climate!$H$5:$H$112,ClimateRows)),MIN(INDEX(Climate!$H$5:$H$112,1):INDEX(Climate!$H$5:$H$112,ROUND($C$9+$C34-DaysPerYear,0))))),IF(ROUND($C$9+$C34,0)<=DaysPerYear,MIN(INDEX(Climate!$E$5:$E$112,$C$9):INDEX(Climate!$E$5:$E$112,ROUND($C$9+$C34,0))),MIN(MIN(INDEX(Climate!$E$5:$E$112,$C$9):INDEX(Climate!$E$5:$E$112,ClimateRows)),MIN(INDEX(Climate!$E$5:$E$112,1):INDEX(Climate!$E$5:$E$112,ROUND($C$9+$C34-DaysPerYear,0)))))) -> 1.96 | G34: =IF($C$11,IF(ROUND($C$9+$C34,0)<=DaysPerYear,MAX(INDEX(Climate!$I$5:$I$112,$C$9):INDEX(Climate!$I$5:$I$112,ROUND($C$9+$C34,0))),MAX(MAX(INDEX(Climate!$I$5:$I$112,$C$9):INDEX(Climate!$I$5:$I$112,ClimateRows)),MAX(INDEX(Climate!$I$5:$I$112,1):INDEX(Climate!$I$5:$I$112,ROUND($C$9+$C34-DaysPerYear,0))))),IF(ROUND($C$9+$C34,0)<=DaysPerYear,MAX(INDEX(Climate!$F$5:$F$112,$C$9):INDEX(Climate!$F$5:$F$112,ROUND($C$9+$C34,0))),MAX(MAX(INDEX(Climate!$F$5:$F$112,$C$9):INDEX(Climate!$F$5:$F$112,ClimateRows)),MAX(INDEX(Climate!$F$5:$F$112,1):INDEX(Climate!$F$5:$F$112,ROUND($C$9+$C34-DaysPerYear,0)))))) -> 24.64 | H34: =IF(AND($F34<INDEX(Crops!$K$5:$K$22,MATCH("Licorice",CropNames,0)),$G34>INDEX(Crops!$M$5:$M$22,MATCH("Licorice",CropNames,0))),"C+H",IF($F34<INDEX(Crops!$K$5:$K$22,MATCH("Licorice",CropNames,0)),"COLD",IF($G34>INDEX(Crops!$M$5:$M$22,MATCH("Licorice",CropNames,0)),"HEAT","✓ ok"))) -> ✓ ok | I34: =IF($C$9+$C34>SeasonEndDay,"✗ no",IF(SeasonEndDay-($C$9+$C34)<3,"barely","✓ yes")) -> ✓ yes | J34: =IF(MAX($C$17,$E$17,$G$17)-MIN($C$17,$E$17,$G$17)<=5,"ok",IF(INDEX(Crops!$G$5:$G$22,MATCH("Licorice",CropNames,0))="N",IF($C$17=MIN($C$17,$E$17,$G$17),"poor",IF($C$17=MAX($C$17,$E$17,$G$17),"great","ok")),IF(INDEX(Crops!$G$5:$G$22,MATCH("Licorice",CropNames,0))="P",IF($E$17=MIN($C$17,$E$17,$G$17),"poor",IF($E$17=MAX($C$17,$E$17,$G$17),"great","ok")),IF($G$17=MIN($C$17,$E$17,$G$17),"poor",IF($G$17=MAX($C$17,$E$17,$G$17),"great","ok"))))) -> ok | K34: =IF($E34>=15,"yes (carrot)",IF($E34>=8,"yes (turnip)",IF($E34>=4,"maybe","no"))) -> yes (turnip) | L34: =ROUND(11/$C34*100*IF(((IF(INDEX(Crops!$G$5:$G$22,MATCH("Licorice",CropNames,0))="N",$C$17,IF(INDEX(Crops!$G$5:$G$22,MATCH("Licorice",CropNames,0))="P",$E$17,$G$17)))+(MAX(0,IF(INDEX(Crops!$G$5:$G$22,MATCH("Licorice",CropNames,0))="N",$C$17,IF(INDEX(Crops!$G$5:$G$22,MATCH("Licorice",CropNames,0))="P",$E$17,$G$17))-MAX(0,INDEX(Crops!$H$5:$H$22,MATCH("Licorice",CropNames,0))-MIN(IF(INDEX(Crops!$G$5:$G$22,MATCH("Licorice",CropNames,0))="N",MIN(150,$C$18+IF($C$13,IFERROR(VLOOKUP($C$14,Fertilizers!$B$6:$E$9,2,FALSE()),0),0)),IF(INDEX(Crops!$G$5:$G$22,MATCH("Licorice",CropNames,0))="P",MIN(150,$E$18+IF($C$13,IFERROR(VLOOKUP($C$14,Fertilizers!$B$6:$E$9,3,FALSE()),0),0)),MIN(150,$G$18+IF($C$13,IFERROR(VLOOKUP($C$14,Fertilizers!$B$6:$E$9,4,FALSE()),0),0)))),0.25*$C34*TicksPerDay)))))/2>75,1.1,IF(((IF(INDEX(Crops!$G$5:$G$22,MATCH("Licorice",CropNames,0))="N",$C$17,IF(INDEX(Crops!$G$5:$G$22,MATCH("Licorice",CropNames,0))="P",$E$17,$G$17)))+(MAX(0,IF(INDEX(Crops!$G$5:$G$22,MATCH("Licorice",CropNames,0))="N",$C$17,IF(INDEX(Crops!$G$5:$G$22,MATCH("Licorice",CropNames,0))="P",$E$17,$G$17))-MAX(0,INDEX(Crops!$H$5:$H$22,MATCH("Licorice",CropNames,0))-MIN(IF(INDEX(Crops!$G$5:$G$22,MATCH("Licorice",CropNames,0))="N",MIN(150,$C$18+IF($C$13,IFERROR(VLOOKUP($C$14,Fertilizers!$B$6:$E$9,2,FALSE()),0),0)),IF(INDEX(Crops!$G$5:$G$22,MATCH("Licorice",CropNames,0))="P",MIN(150,$E$18+IF($C$13,IFERROR(VLOOKUP($C$14,Fertilizers!$B$6:$E$9,3,FALSE()),0),0)),MIN(150,$G$18+IF($C$13,IFERROR(VLOOKUP($C$14,Fertilizers!$B$6:$E$9,4,FALSE()),0),0)))),0.25*$C34*TicksPerDay)))))/2>50,1,IF(((IF(INDEX(Crops!$G$5:$G$22,MATCH("Licorice",CropNames,0))="N",$C$17,IF(INDEX(Crops!$G$5:$G$22,MATCH("Licorice",CropNames,0))="P",$E$17,$G$17)))+(MAX(0,IF(INDEX(Crops!$G$5:$G$22,MATCH("Licorice",CropNames,0))="N",$C$17,IF(INDEX(Crops!$G$5:$G$22,MATCH("Licorice",CropNames,0))="P",$E$17,$G$17))-MAX(0,INDEX(Crops!$H$5:$H$22,MATCH("Licorice",CropNames,0))-MIN(IF(INDEX(Crops!$G$5:$G$22,MATCH("Licorice",CropNames,0))="N",MIN(150,$C$18+IF($C$13,IFERROR(VLOOKUP($C$14,Fertilizers!$B$6:$E$9,2,FALSE()),0),0)),IF(INDEX(Crops!$G$5:$G$22,MATCH("Licorice",CropNames,0))="P",MIN(150,$E$18+IF($C$13,IFERROR(VLOOKUP($C$14,Fertilizers!$B$6:$E$9,3,FALSE()),0),0)),MIN(150,$G$18+IF($C$13,IFERROR(VLOOKUP($C$14,Fertilizers!$B$6:$E$9,4,FALSE()),0),0)))),0.25*$C34*TicksPerDay)))))/2>35,0.9,IF(((IF(INDEX(Crops!$G$5:$G$22,MATCH("Licorice",CropNames,0))="N",$C$17,IF(INDEX(Crops!$G$5:$G$22,MATCH("Licorice",CropNames,0))="P",$E$17,$G$17)))+(MAX(0,IF(INDEX(Crops!$G$5:$G$22,MATCH("Licorice",CropNames,0))="N",$C$17,IF(INDEX(Crops!$G$5:$G$22,MATCH("Licorice",CropNames,0))="P",$E$17,$G$17))-MAX(0,INDEX(Crops!$H$5:$H$22,MATCH("Licorice",CropNames,0))-MIN(IF(INDEX(Crops!$G$5:$G$22,MATCH("Licorice",CropNames,0))="N",MIN(150,$C$18+IF($C$13,IFERROR(VLOOKUP($C$14,Fertilizers!$B$6:$E$9,2,FALSE()),0),0)),IF(INDEX(Crops!$G$5:$G$22,MATCH("Licorice",CropNames,0))="P",MIN(150,$E$18+IF($C$13,IFERROR(VLOOKUP($C$14,Fertilizers!$B$6:$E$9,3,FALSE()),0),0)),MIN(150,$G$18+IF($C$13,IFERROR(VLOOKUP($C$14,Fertilizers!$B$6:$E$9,4,FALSE()),0),0)))),0.25*$C34*TicksPerDay)))))/2>20,0.6,IF(((IF(INDEX(Crops!$G$5:$G$22,MATCH("Licorice",CropNames,0))="N",$C$17,IF(INDEX(Crops!$G$5:$G$22,MATCH("Licorice",CropNames,0))="P",$E$17,$G$17)))+(MAX(0,IF(INDEX(Crops!$G$5:$G$22,MATCH("Licorice",CropNames,0))="N",$C$17,IF(INDEX(Crops!$G$5:$G$22,MATCH("Licorice",CropNames,0))="P",$E$17,$G$17))-MAX(0,INDEX(Crops!$H$5:$H$22,MATCH("Licorice",CropNames,0))-MIN(IF(INDEX(Crops!$G$5:$G$22,MATCH("Licorice",CropNames,0))="N",MIN(150,$C$18+IF($C$13,IFERROR(VLOOKUP($C$14,Fertilizers!$B$6:$E$9,2,FALSE()),0),0)),IF(INDEX(Crops!$G$5:$G$22,MATCH("Licorice",CropNames,0))="P",MIN(150,$E$18+IF($C$13,IFERROR(VLOOKUP($C$14,Fertilizers!$B$6:$E$9,3,FALSE()),0),0)),MIN(150,$G$18+IF($C$13,IFERROR(VLOOKUP($C$14,Fertilizers!$B$6:$E$9,4,FALSE()),0),0)))),0.25*$C34*TicksPerDay)))))/2>5,0.3,0.1)))))*IF($I34="✓ yes",1,IF($I34="barely",0.6,0))*IF($H34="✓ ok",1,IFERROR(IF(ISBLANK(INDEX(Crops!$O$5:$O$22,MATCH("Licorice",CropNames,0))),DefaultStuntMul,INDEX(Crops!$O$5:$O$22,MATCH("Licorice",CropNames,0))),DefaultStuntMul))*IF($J34="poor",0.7,IF($J34="great",1.2,1))*IF(LEFT($K34,3)="yes",1.3,IF($K34="maybe",1.1,1)),1) -> 53.6 | M34: =IF($I34="✗ no","won't finish",IF($H34="✓ ok",IF($L34>=RANK_TOP3,"top pick",IF($L34>=RANK_TOP10,"good","ok")),"risk: "&$H34)) -> good
B35: Onion | C35: =INDEX(Crops!$F$5:$F$22,MATCH("Onion",CropNames,0)) -> 13.86 | D35: =$C$9&"→"&IF(ROUND($C$9+$C35,0)>DaysPerYear,ROUND($C$9+$C35-DaysPerYear,0),ROUND($C$9+$C35,0)) -> 50→64 | E35: =MAX(0,ROUND(SeasonEndDay-($C$9+$C35),0)) -> 20 | F35: =IF($C$11,IF(ROUND($C$9+$C35,0)<=DaysPerYear,MIN(INDEX(Climate!$H$5:$H$112,$C$9):INDEX(Climate!$H$5:$H$112,ROUND($C$9+$C35,0))),MIN(MIN(INDEX(Climate!$H$5:$H$112,$C$9):INDEX(Climate!$H$5:$H$112,ClimateRows)),MIN(INDEX(Climate!$H$5:$H$112,1):INDEX(Climate!$H$5:$H$112,ROUND($C$9+$C35-DaysPerYear,0))))),IF(ROUND($C$9+$C35,0)<=DaysPerYear,MIN(INDEX(Climate!$E$5:$E$112,$C$9):INDEX(Climate!$E$5:$E$112,ROUND($C$9+$C35,0))),MIN(MIN(INDEX(Climate!$E$5:$E$112,$C$9):INDEX(Climate!$E$5:$E$112,ClimateRows)),MIN(INDEX(Climate!$E$5:$E$112,1):INDEX(Climate!$E$5:$E$112,ROUND($C$9+$C35-DaysPerYear,0)))))) -> 4.66 | G35: =IF($C$11,IF(ROUND($C$9+$C35,0)<=DaysPerYear,MAX(INDEX(Climate!$I$5:$I$112,$C$9):INDEX(Climate!$I$5:$I$112,ROUND($C$9+$C35,0))),MAX(MAX(INDEX(Climate!$I$5:$I$112,$C$9):INDEX(Climate!$I$5:$I$112,ClimateRows)),MAX(INDEX(Climate!$I$5:$I$112,1):INDEX(Climate!$I$5:$I$112,ROUND($C$9+$C35-DaysPerYear,0))))),IF(ROUND($C$9+$C35,0)<=DaysPerYear,MAX(INDEX(Climate!$F$5:$F$112,$C$9):INDEX(Climate!$F$5:$F$112,ROUND($C$9+$C35,0))),MAX(MAX(INDEX(Climate!$F$5:$F$112,$C$9):INDEX(Climate!$F$5:$F$112,ClimateRows)),MAX(INDEX(Climate!$F$5:$F$112,1):INDEX(Climate!$F$5:$F$112,ROUND($C$9+$C35-DaysPerYear,0)))))) -> 24.64 | H35: =IF(AND($F35<INDEX(Crops!$K$5:$K$22,MATCH("Onion",CropNames,0)),$G35>INDEX(Crops!$M$5:$M$22,MATCH("Onion",CropNames,0))),"C+H",IF($F35<INDEX(Crops!$K$5:$K$22,MATCH("Onion",CropNames,0)),"COLD",IF($G35>INDEX(Crops!$M$5:$M$22,MATCH("Onion",CropNames,0)),"HEAT","✓ ok"))) -> ✓ ok | I35: =IF($C$9+$C35>SeasonEndDay,"✗ no",IF(SeasonEndDay-($C$9+$C35)<3,"barely","✓ yes")) -> ✓ yes | J35: =IF(MAX($C$17,$E$17,$G$17)-MIN($C$17,$E$17,$G$17)<=5,"ok",IF(INDEX(Crops!$G$5:$G$22,MATCH("Onion",CropNames,0))="N",IF($C$17=MIN($C$17,$E$17,$G$17),"poor",IF($C$17=MAX($C$17,$E$17,$G$17),"great","ok")),IF(INDEX(Crops!$G$5:$G$22,MATCH("Onion",CropNames,0))="P",IF($E$17=MIN($C$17,$E$17,$G$17),"poor",IF($E$17=MAX($C$17,$E$17,$G$17),"great","ok")),IF($G$17=MIN($C$17,$E$17,$G$17),"poor",IF($G$17=MAX($C$17,$E$17,$G$17),"great","ok"))))) -> ok | K35: =IF($E35>=15,"yes (carrot)",IF($E35>=8,"yes (turnip)",IF($E35>=4,"maybe","no"))) -> yes (carrot) | L35: =ROUND(12/$C35*100*IF(((IF(INDEX(Crops!$G$5:$G$22,MATCH("Onion",CropNames,0))="N",$C$17,IF(INDEX(Crops!$G$5:$G$22,MATCH("Onion",CropNames,0))="P",$E$17,$G$17)))+(MAX(0,IF(INDEX(Crops!$G$5:$G$22,MATCH("Onion",CropNames,0))="N",$C$17,IF(INDEX(Crops!$G$5:$G$22,MATCH("Onion",CropNames,0))="P",$E$17,$G$17))-MAX(0,INDEX(Crops!$H$5:$H$22,MATCH("Onion",CropNames,0))-MIN(IF(INDEX(Crops!$G$5:$G$22,MATCH("Onion",CropNames,0))="N",MIN(150,$C$18+IF($C$13,IFERROR(VLOOKUP($C$14,Fertilizers!$B$6:$E$9,2,FALSE()),0),0)),IF(INDEX(Crops!$G$5:$G$22,MATCH("Onion",CropNames,0))="P",MIN(150,$E$18+IF($C$13,IFERROR(VLOOKUP($C$14,Fertilizers!$B$6:$E$9,3,FALSE()),0),0)),MIN(150,$G$18+IF($C$13,IFERROR(VLOOKUP($C$14,Fertilizers!$B$6:$E$9,4,FALSE()),0),0)))),0.25*$C35*TicksPerDay)))))/2>75,1.1,IF(((IF(INDEX(Crops!$G$5:$G$22,MATCH("Onion",CropNames,0))="N",$C$17,IF(INDEX(Crops!$G$5:$G$22,MATCH("Onion",CropNames,0))="P",$E$17,$G$17)))+(MAX(0,IF(INDEX(Crops!$G$5:$G$22,MATCH("Onion",CropNames,0))="N",$C$17,IF(INDEX(Crops!$G$5:$G$22,MATCH("Onion",CropNames,0))="P",$E$17,$G$17))-MAX(0,INDEX(Crops!$H$5:$H$22,MATCH("Onion",CropNames,0))-MIN(IF(INDEX(Crops!$G$5:$G$22,MATCH("Onion",CropNames,0))="N",MIN(150,$C$18+IF($C$13,IFERROR(VLOOKUP($C$14,Fertilizers!$B$6:$E$9,2,FALSE()),0),0)),IF(INDEX(Crops!$G$5:$G$22,MATCH("Onion",CropNames,0))="P",MIN(150,$E$18+IF($C$13,IFERROR(VLOOKUP($C$14,Fertilizers!$B$6:$E$9,3,FALSE()),0),0)),MIN(150,$G$18+IF($C$13,IFERROR(VLOOKUP($C$14,Fertilizers!$B$6:$E$9,4,FALSE()),0),0)))),0.25*$C35*TicksPerDay)))))/2>50,1,IF(((IF(INDEX(Crops!$G$5:$G$22,MATCH("Onion",CropNames,0))="N",$C$17,IF(INDEX(Crops!$G$5:$G$22,MATCH("Onion",CropNames,0))="P",$E$17,$G$17)))+(MAX(0,IF(INDEX(Crops!$G$5:$G$22,MATCH("Onion",CropNames,0))="N",$C$17,IF(INDEX(Crops!$G$5:$G$22,MATCH("Onion",CropNames,0))="P",$E$17,$G$17))-MAX(0,INDEX(Crops!$H$5:$H$22,MATCH("Onion",CropNames,0))-MIN(IF(INDEX(Crops!$G$5:$G$22,MATCH("Onion",CropNames,0))="N",MIN(150,$C$18+IF($C$13,IFERROR(VLOOKUP($C$14,Fertilizers!$B$6:$E$9,2,FALSE()),0),0)),IF(INDEX(Crops!$G$5:$G$22,MATCH("Onion",CropNames,0))="P",MIN(150,$E$18+IF($C$13,IFERROR(VLOOKUP($C$14,Fertilizers!$B$6:$E$9,3,FALSE()),0),0)),MIN(150,$G$18+IF($C$13,IFERROR(VLOOKUP($C$14,Fertilizers!$B$6:$E$9,4,FALSE()),0),0)))),0.25*$C35*TicksPerDay)))))/2>35,0.9,IF(((IF(INDEX(Crops!$G$5:$G$22,MATCH("Onion",CropNames,0))="N",$C$17,IF(INDEX(Crops!$G$5:$G$22,MATCH("Onion",CropNames,0))="P",$E$17,$G$17)))+(MAX(0,IF(INDEX(Crops!$G$5:$G$22,MATCH("Onion",CropNames,0))="N",$C$17,IF(INDEX(Crops!$G$5:$G$22,MATCH("Onion",CropNames,0))="P",$E$17,$G$17))-MAX(0,INDEX(Crops!$H$5:$H$22,MATCH("Onion",CropNames,0))-MIN(IF(INDEX(Crops!$G$5:$G$22,MATCH("Onion",CropNames,0))="N",MIN(150,$C$18+IF($C$13,IFERROR(VLOOKUP($C$14,Fertilizers!$B$6:$E$9,2,FALSE()),0),0)),IF(INDEX(Crops!$G$5:$G$22,MATCH("Onion",CropNames,0))="P",MIN(150,$E$18+IF($C$13,IFERROR(VLOOKUP($C$14,Fertilizers!$B$6:$E$9,3,FALSE()),0),0)),MIN(150,$G$18+IF($C$13,IFERROR(VLOOKUP($C$14,Fertilizers!$B$6:$E$9,4,FALSE()),0),0)))),0.25*$C35*TicksPerDay)))))/2>20,0.6,IF(((IF(INDEX(Crops!$G$5:$G$22,MATCH("Onion",CropNames,0))="N",$C$17,IF(INDEX(Crops!$G$5:$G$22,MATCH("Onion",CropNames,0))="P",$E$17,$G$17)))+(MAX(0,IF(INDEX(Crops!$G$5:$G$22,MATCH("Onion",CropNames,0))="N",$C$17,IF(INDEX(Crops!$G$5:$G$22,MATCH("Onion",CropNames,0))="P",$E$17,$G$17))-MAX(0,INDEX(Crops!$H$5:$H$22,MATCH("Onion",CropNames,0))-MIN(IF(INDEX(Crops!$G$5:$G$22,MATCH("Onion",CropNames,0))="N",MIN(150,$C$18+IF($C$13,IFERROR(VLOOKUP($C$14,Fertilizers!$B$6:$E$9,2,FALSE()),0),0)),IF(INDEX(Crops!$G$5:$G$22,MATCH("Onion",CropNames,0))="P",MIN(150,$E$18+IF($C$13,IFERROR(VLOOKUP($C$14,Fertilizers!$B$6:$E$9,3,FALSE()),0),0)),MIN(150,$G$18+IF($C$13,IFERROR(VLOOKUP($C$14,Fertilizers!$B$6:$E$9,4,FALSE()),0),0)))),0.25*$C35*TicksPerDay)))))/2>5,0.3,0.1)))))*IF($I35="✓ yes",1,IF($I35="barely",0.6,0))*IF($H35="✓ ok",1,IFERROR(IF(ISBLANK(INDEX(Crops!$O$5:$O$22,MATCH("Onion",CropNames,0))),DefaultStuntMul,INDEX(Crops!$O$5:$O$22,MATCH("Onion",CropNames,0))),DefaultStuntMul))*IF($J35="poor",0.7,IF($J35="great",1.2,1))*IF(LEFT($K35,3)="yes",1.3,IF($K35="maybe",1.1,1)),1) -> 101.3 | M35: =IF($I35="✗ no","won't finish",IF($H35="✓ ok",IF($L35>=RANK_TOP3,"top pick",IF($L35>=RANK_TOP10,"good","ok")),"risk: "&$H35)) -> top pick
B36: Turnip | C36: =INDEX(Crops!$F$5:$F$22,MATCH("Turnip",CropNames,0)) -> 7.2 | D36: =$C$9&"→"&IF(ROUND($C$9+$C36,0)>DaysPerYear,ROUND($C$9+$C36-DaysPerYear,0),ROUND($C$9+$C36,0)) -> 50→57 | E36: =MAX(0,ROUND(SeasonEndDay-($C$9+$C36),0)) -> 27 | F36: =IF($C$11,IF(ROUND($C$9+$C36,0)<=DaysPerYear,MIN(INDEX(Climate!$H$5:$H$112,$C$9):INDEX(Climate!$H$5:$H$112,ROUND($C$9+$C36,0))),MIN(MIN(INDEX(Climate!$H$5:$H$112,$C$9):INDEX(Climate!$H$5:$H$112,ClimateRows)),MIN(INDEX(Climate!$H$5:$H$112,1):INDEX(Climate!$H$5:$H$112,ROUND($C$9+$C36-DaysPerYear,0))))),IF(ROUND($C$9+$C36,0)<=DaysPerYear,MIN(INDEX(Climate!$E$5:$E$112,$C$9):INDEX(Climate!$E$5:$E$112,ROUND($C$9+$C36,0))),MIN(MIN(INDEX(Climate!$E$5:$E$112,$C$9):INDEX(Climate!$E$5:$E$112,ClimateRows)),MIN(INDEX(Climate!$E$5:$E$112,1):INDEX(Climate!$E$5:$E$112,ROUND($C$9+$C36-DaysPerYear,0)))))) -> 4.66 | G36: =IF($C$11,IF(ROUND($C$9+$C36,0)<=DaysPerYear,MAX(INDEX(Climate!$I$5:$I$112,$C$9):INDEX(Climate!$I$5:$I$112,ROUND($C$9+$C36,0))),MAX(MAX(INDEX(Climate!$I$5:$I$112,$C$9):INDEX(Climate!$I$5:$I$112,ClimateRows)),MAX(INDEX(Climate!$I$5:$I$112,1):INDEX(Climate!$I$5:$I$112,ROUND($C$9+$C36-DaysPerYear,0))))),IF(ROUND($C$9+$C36,0)<=DaysPerYear,MAX(INDEX(Climate!$F$5:$F$112,$C$9):INDEX(Climate!$F$5:$F$112,ROUND($C$9+$C36,0))),MAX(MAX(INDEX(Climate!$F$5:$F$112,$C$9):INDEX(Climate!$F$5:$F$112,ClimateRows)),MAX(INDEX(Climate!$F$5:$F$112,1):INDEX(Climate!$F$5:$F$112,ROUND($C$9+$C36-DaysPerYear,0)))))) -> 24.07 | H36: =IF(AND($F36<INDEX(Crops!$K$5:$K$22,MATCH("Turnip",CropNames,0)),$G36>INDEX(Crops!$M$5:$M$22,MATCH("Turnip",CropNames,0))),"C+H",IF($F36<INDEX(Crops!$K$5:$K$22,MATCH("Turnip",CropNames,0)),"COLD",IF($G36>INDEX(Crops!$M$5:$M$22,MATCH("Turnip",CropNames,0)),"HEAT","✓ ok"))) -> ✓ ok | I36: =IF($C$9+$C36>SeasonEndDay,"✗ no",IF(SeasonEndDay-($C$9+$C36)<3,"barely","✓ yes")) -> ✓ yes | J36: =IF(MAX($C$17,$E$17,$G$17)-MIN($C$17,$E$17,$G$17)<=5,"ok",IF(INDEX(Crops!$G$5:$G$22,MATCH("Turnip",CropNames,0))="N",IF($C$17=MIN($C$17,$E$17,$G$17),"poor",IF($C$17=MAX($C$17,$E$17,$G$17),"great","ok")),IF(INDEX(Crops!$G$5:$G$22,MATCH("Turnip",CropNames,0))="P",IF($E$17=MIN($C$17,$E$17,$G$17),"poor",IF($E$17=MAX($C$17,$E$17,$G$17),"great","ok")),IF($G$17=MIN($C$17,$E$17,$G$17),"poor",IF($G$17=MAX($C$17,$E$17,$G$17),"great","ok"))))) -> ok | K36: =IF($E36>=15,"yes (carrot)",IF($E36>=8,"yes (turnip)",IF($E36>=4,"maybe","no"))) -> yes (carrot) | L36: =ROUND(7/$C36*100*IF(((IF(INDEX(Crops!$G$5:$G$22,MATCH("Turnip",CropNames,0))="N",$C$17,IF(INDEX(Crops!$G$5:$G$22,MATCH("Turnip",CropNames,0))="P",$E$17,$G$17)))+(MAX(0,IF(INDEX(Crops!$G$5:$G$22,MATCH("Turnip",CropNames,0))="N",$C$17,IF(INDEX(Crops!$G$5:$G$22,MATCH("Turnip",CropNames,0))="P",$E$17,$G$17))-MAX(0,INDEX(Crops!$H$5:$H$22,MATCH("Turnip",CropNames,0))-MIN(IF(INDEX(Crops!$G$5:$G$22,MATCH("Turnip",CropNames,0))="N",MIN(150,$C$18+IF($C$13,IFERROR(VLOOKUP($C$14,Fertilizers!$B$6:$E$9,2,FALSE()),0),0)),IF(INDEX(Crops!$G$5:$G$22,MATCH("Turnip",CropNames,0))="P",MIN(150,$E$18+IF($C$13,IFERROR(VLOOKUP($C$14,Fertilizers!$B$6:$E$9,3,FALSE()),0),0)),MIN(150,$G$18+IF($C$13,IFERROR(VLOOKUP($C$14,Fertilizers!$B$6:$E$9,4,FALSE()),0),0)))),0.25*$C36*TicksPerDay)))))/2>75,1.1,IF(((IF(INDEX(Crops!$G$5:$G$22,MATCH("Turnip",CropNames,0))="N",$C$17,IF(INDEX(Crops!$G$5:$G$22,MATCH("Turnip",CropNames,0))="P",$E$17,$G$17)))+(MAX(0,IF(INDEX(Crops!$G$5:$G$22,MATCH("Turnip",CropNames,0))="N",$C$17,IF(INDEX(Crops!$G$5:$G$22,MATCH("Turnip",CropNames,0))="P",$E$17,$G$17))-MAX(0,INDEX(Crops!$H$5:$H$22,MATCH("Turnip",CropNames,0))-MIN(IF(INDEX(Crops!$G$5:$G$22,MATCH("Turnip",CropNames,0))="N",MIN(150,$C$18+IF($C$13,IFERROR(VLOOKUP($C$14,Fertilizers!$B$6:$E$9,2,FALSE()),0),0)),IF(INDEX(Crops!$G$5:$G$22,MATCH("Turnip",CropNames,0))="P",MIN(150,$E$18+IF($C$13,IFERROR(VLOOKUP($C$14,Fertilizers!$B$6:$E$9,3,FALSE()),0),0)),MIN(150,$G$18+IF($C$13,IFERROR(VLOOKUP($C$14,Fertilizers!$B$6:$E$9,4,FALSE()),0),0)))),0.25*$C36*TicksPerDay)))))/2>50,1,IF(((IF(INDEX(Crops!$G$5:$G$22,MATCH("Turnip",CropNames,0))="N",$C$17,IF(INDEX(Crops!$G$5:$G$22,MATCH("Turnip",CropNames,0))="P",$E$17,$G$17)))+(MAX(0,IF(INDEX(Crops!$G$5:$G$22,MATCH("Turnip",CropNames,0))="N",$C$17,IF(INDEX(Crops!$G$5:$G$22,MATCH("Turnip",CropNames,0))="P",$E$17,$G$17))-MAX(0,INDEX(Crops!$H$5:$H$22,MATCH("Turnip",CropNames,0))-MIN(IF(INDEX(Crops!$G$5:$G$22,MATCH("Turnip",CropNames,0))="N",MIN(150,$C$18+IF($C$13,IFERROR(VLOOKUP($C$14,Fertilizers!$B$6:$E$9,2,FALSE()),0),0)),IF(INDEX(Crops!$G$5:$G$22,MATCH("Turnip",CropNames,0))="P",MIN(150,$E$18+IF($C$13,IFERROR(VLOOKUP($C$14,Fertilizers!$B$6:$E$9,3,FALSE()),0),0)),MIN(150,$G$18+IF($C$13,IFERROR(VLOOKUP($C$14,Fertilizers!$B$6:$E$9,4,FALSE()),0),0)))),0.25*$C36*TicksPerDay)))))/2>35,0.9,IF(((IF(INDEX(Crops!$G$5:$G$22,MATCH("Turnip",CropNames,0))="N",$C$17,IF(INDEX(Crops!$G$5:$G$22,MATCH("Turnip",CropNames,0))="P",$E$17,$G$17)))+(MAX(0,IF(INDEX(Crops!$G$5:$G$22,MATCH("Turnip",CropNames,0))="N",$C$17,IF(INDEX(Crops!$G$5:$G$22,MATCH("Turnip",CropNames,0))="P",$E$17,$G$17))-MAX(0,INDEX(Crops!$H$5:$H$22,MATCH("Turnip",CropNames,0))-MIN(IF(INDEX(Crops!$G$5:$G$22,MATCH("Turnip",CropNames,0))="N",MIN(150,$C$18+IF($C$13,IFERROR(VLOOKUP($C$14,Fertilizers!$B$6:$E$9,2,FALSE()),0),0)),IF(INDEX(Crops!$G$5:$G$22,MATCH("Turnip",CropNames,0))="P",MIN(150,$E$18+IF($C$13,IFERROR(VLOOKUP($C$14,Fertilizers!$B$6:$E$9,3,FALSE()),0),0)),MIN(150,$G$18+IF($C$13,IFERROR(VLOOKUP($C$14,Fertilizers!$B$6:$E$9,4,FALSE()),0),0)))),0.25*$C36*TicksPerDay)))))/2>20,0.6,IF(((IF(INDEX(Crops!$G$5:$G$22,MATCH("Turnip",CropNames,0))="N",$C$17,IF(INDEX(Crops!$G$5:$G$22,MATCH("Turnip",CropNames,0))="P",$E$17,$G$17)))+(MAX(0,IF(INDEX(Crops!$G$5:$G$22,MATCH("Turnip",CropNames,0))="N",$C$17,IF(INDEX(Crops!$G$5:$G$22,MATCH("Turnip",CropNames,0))="P",$E$17,$G$17))-MAX(0,INDEX(Crops!$H$5:$H$22,MATCH("Turnip",CropNames,0))-MIN(IF(INDEX(Crops!$G$5:$G$22,MATCH("Turnip",CropNames,0))="N",MIN(150,$C$18+IF($C$13,IFERROR(VLOOKUP($C$14,Fertilizers!$B$6:$E$9,2,FALSE()),0),0)),IF(INDEX(Crops!$G$5:$G$22,MATCH("Turnip",CropNames,0))="P",MIN(150,$E$18+IF($C$13,IFERROR(VLOOKUP($C$14,Fertilizers!$B$6:$E$9,3,FALSE()),0),0)),MIN(150,$G$18+IF($C$13,IFERROR(VLOOKUP($C$14,Fertilizers!$B$6:$E$9,4,FALSE()),0),0)))),0.25*$C36*TicksPerDay)))))/2>5,0.3,0.1)))))*IF($I36="✓ yes",1,IF($I36="barely",0.6,0))*IF($H36="✓ ok",1,IFERROR(IF(ISBLANK(INDEX(Crops!$O$5:$O$22,MATCH("Turnip",CropNames,0))),DefaultStuntMul,INDEX(Crops!$O$5:$O$22,MATCH("Turnip",CropNames,0))),DefaultStuntMul))*IF($J36="poor",0.7,IF($J36="great",1.2,1))*IF(LEFT($K36,3)="yes",1.3,IF($K36="maybe",1.1,1)),1) -> 126.4 | M36: =IF($I36="✗ no","won't finish",IF($H36="✓ ok",IF($L36>=RANK_TOP3,"top pick",IF($L36>=RANK_TOP10,"good","ok")),"risk: "&$H36)) -> top pick
